Workbook
Name CENEN13606Lekarska_prepustacia_sprava: '[1]Hospital Discharge Report '!#REF!

Sheet ConceptMaps
A1: Instance | B1: Name | C1: URL | D1: Title | E1: Description | F1: Status | G1: SourceUri | H1: TargetUri | I1: Experimental
A2: IndicatorsOah2FHIR | B2: IndicatorsOah2FHIR | C2: ="http://hl7.eu/fhir/ig/oah/ConceptMap/"&A2 -> http://hl7.eu/fhir/ig/oah/ConceptMap/IndicatorsOah2FHIR | D2: OAH Indicators Model to this guide Map | E2: OAH Indicators Model to this guide mapping | F2: draft | I2: true
A3: SimpleIndicatorOah2FHIR | B3: SimpleIndicatorOah2FHIR | C3: ="http://hl7.eu/fhir/ig/oah/ConceptMap/"&A3 -> http://hl7.eu/fhir/ig/oah/ConceptMap/SimpleIndicatorOah2FHIR | D3: OAH Simple Indicator Model to this guide Map | E3: OAH simple Indicator Model to this guide mapping | F3: draft
A4: StructuredIndicatorOah2FHIR | B4: StructuredIndicatorOah2FHIR | C4: ="http://hl7.eu/fhir/ig/oah/ConceptMap/"&A4 -> http://hl7.eu/fhir/ig/oah/ConceptMap/StructuredIndicatorOah2FHIR | D4: OAH Structured Indicator Model to this guide Map | E4: OAH Structured Indicator Model to this guide mapping | F4: draft
A5: SampleOah2FHIR | B5: SampleOah2FHIR | C5: ="http://hl7.eu/fhir/ig/oah/ConceptMap/"&A5 -> http://hl7.eu/fhir/ig/oah/ConceptMap/SampleOah2FHIR | D5: OAH Sample Model to this guide Map | E5: OAH Sample Model to this guide mapping | F5: draft
A6: DataSetOah2FHIR | B6: DataSetOah2FHIR | C6: ="http://hl7.eu/fhir/ig/oah/ConceptMap/"&A6 -> http://hl7.eu/fhir/ig/oah/ConceptMap/DataSetOah2FHIR | D6: OAH Data Set Model to this guide Map | E6: OAH Data Set Model to this guide mapping | F6: draft
A7: HealthIndicatorsOah2FHIR | B7: HealthIndicatorsOah2FHIR | C7: ="http://hl7.eu/fhir/ig/oah/ConceptMap/"&A7 -> http://hl7.eu/fhir/ig/oah/ConceptMap/HealthIndicatorsOah2FHIR | D7: OAH Data Set Model to this guide Map | E7: OAH Data Set Model to this guide mapping | F7: draft
A8: HealthMeasureOah2FHIR | B8: HealthMeasureOah2FHIR | C8: ="http://hl7.eu/fhir/ig/oah/ConceptMap/"&A8 -> http://hl7.eu/fhir/ig/oah/ConceptMap/HealthMeasureOah2FHIR | D8: OAH Data Set Model to this guide Map | E8: OAH Data Set Model to this guide mapping | F8: draft

Sheet LogicalModels
A1: Id | B1: Name | C1: Title | D1: Description
A2: IndicatorsOah | B2: IndicatorsOah | C2: OAH indicators | D2: Set of OneAquaHealth indicators including : (a) biological quality (b) hydromorphological quality (c) hydromorphological quality and (d) Biological indicators of health risks
A3: SimpleIndicator | B3: SimpleIndicatorOah | C3: Simple Indicator | D3: Model describing the common attributes of a simple indicator wiith a single value
A4: StructuredIndicator | B4: StructuredIndicatorOah | C4: Structured Indicator | D4: Model describing the common attributes of a structured indicator with multiple measures
A5: Sample | B5: SampleOah | C5: Sample | D5: Information about the sample used for this measure
A6: DataSet | B6: DataSetOah | C6: OAH Data Set | D6: Model describing the data set usd for the OneAquaHealth project
A7: HealthIndicators | B7: HealthIndicatorsOah | C7: Health Indicators | D7: Set of OneAquaHealth Health and Wellness indicators
A8: HealthMeasure | B8: HealthMeasureOah | C8: Health measure | D8: Model describing the common attributes of a simple health and wellness indicator

Sheet HealthIndicatorsOah2FHIR
A1: Group Source | B1: Group Target | C1: Source Code | D1: Source Display | E1: Target Code | F1: Target Display | G1: Equivalence | H1: Comment
A2: ="http://hl7.eu/fhir/ig/oah/StructureDefinition/"&LogicalModels!$A$7 -> http://hl7.eu/fhir/ig/oah/StructureDefinition/HealthIndicators | B2: http://hl7.eu/fhir/ig/oah/StructureDefinition/observation-health-measure-oah | C2: =HealthIndicatorsOah!A2 -> diseasePrevalence | D2: =HealthIndicatorsOah!D2 -> Cases of disease prevalence | E2: Observation | G2: relatedto
A3: ="http://hl7.eu/fhir/ig/oah/StructureDefinition/"&LogicalModels!$A$7 -> http://hl7.eu/fhir/ig/oah/StructureDefinition/HealthIndicators | B3: http://hl7.eu/fhir/ig/oah/StructureDefinition/observation-health-measure-oah | C3: =HealthIndicatorsOah!A3 -> diseasePrevalence.highBloodPression | D3: =HealthIndicatorsOah!D3 -> % of people with high blood pressure (prevalence) | E3: Observation | F3: ="" | G3: relatedto
A4: ="http://hl7.eu/fhir/ig/oah/StructureDefinition/"&LogicalModels!$A$7 -> http://hl7.eu/fhir/ig/oah/StructureDefinition/HealthIndicators | B4: http://hl7.eu/fhir/ig/oah/StructureDefinition/observation-health-measure-oah | C4: =HealthIndicatorsOah!A4 -> diseasePrevalence.hypertension | D4: =HealthIndicatorsOah!D4 -> % of people under treatment for hypertension | E4: Observation | G4: relatedto
A5: ="http://hl7.eu/fhir/ig/oah/StructureDefinition/"&LogicalModels!$A$7 -> http://hl7.eu/fhir/ig/oah/StructureDefinition/HealthIndicators | B5: http://hl7.eu/fhir/ig/oah/StructureDefinition/observation-health-measure-oah | C5: =HealthIndicatorsOah!A5 -> diseasePrevalence.highBloodPressionTreatment | D5: =HealthIndicatorsOah!D5 -> % of people under treatment for high blood pressure | E5: Observation | G5: relatedto
A6: ="http://hl7.eu/fhir/ig/oah/StructureDefinition/"&LogicalModels!$A$7 -> http://hl7.eu/fhir/ig/oah/StructureDefinition/HealthIndicators | B6: http://hl7.eu/fhir/ig/oah/StructureDefinition/observation-health-measure-oah | C6: =HealthIndicatorsOah!A6 -> diseasePrevalence.obesity | D6: =HealthIndicatorsOah!D6 -> % of people affected from obesity | E6: Observation | G6: relatedto
A7: ="http://hl7.eu/fhir/ig/oah/StructureDefinition/"&LogicalModels!$A$7 -> http://hl7.eu/fhir/ig/oah/StructureDefinition/HealthIndicators | B7: http://hl7.eu/fhir/ig/oah/StructureDefinition/observation-health-measure-oah | C7: =HealthIndicatorsOah!A7 -> diseasePrevalence.cholesterolemia190 | D7: =HealthIndicatorsOah!D7 -> % of people with high total cholesterolemia (>=190 mg/dl) | E7: Observation | G7: relatedto
A8: ="http://hl7.eu/fhir/ig/oah/StructureDefinition/"&LogicalModels!$A$7 -> http://hl7.eu/fhir/ig/oah/StructureDefinition/HealthIndicators | B8: http://hl7.eu/fhir/ig/oah/StructureDefinition/observation-health-measure-oah | C8: =HealthIndicatorsOah!A8 -> diseasePrevalence.hypercholesterolemiaTreatment | D8: =HealthIndicatorsOah!D8 -> % of people under treatment for hypercholesterolemia | E8: Observation | G8: relatedto
A9: ="http://hl7.eu/fhir/ig/oah/StructureDefinition/"&LogicalModels!$A$7 -> http://hl7.eu/fhir/ig/oah/StructureDefinition/HealthIndicators | B9: http://hl7.eu/fhir/ig/oah/StructureDefinition/observation-health-measure-oah | C9: =HealthIndicatorsOah!A9 -> diseasePrevalence.cholesterolemia240 | D9: =HealthIndicatorsOah!D9 -> % of people with high total cholesterolemia (>=240 mg/dl) | E9: Observation | G9: relatedto
A10: ="http://hl7.eu/fhir/ig/oah/StructureDefinition/"&LogicalModels!$A$7 -> http://hl7.eu/fhir/ig/oah/StructureDefinition/HealthIndicators | B10: http://hl7.eu/fhir/ig/oah/StructureDefinition/observation-health-measure-oah | C10: =HealthIndicatorsOah!A10 -> diseasePrevalence.diabetes | D10: =HealthIndicatorsOah!D10 -> % of people with high blood sugar/diabetes | E10: Observation | G10: relatedto
A11: ="http://hl7.eu/fhir/ig/oah/StructureDefinition/"&LogicalModels!$A$7 -> http://hl7.eu/fhir/ig/oah/StructureDefinition/HealthIndicators | B11: http://hl7.eu/fhir/ig/oah/StructureDefinition/observation-health-measure-oah | C11: =HealthIndicatorsOah!A11 -> diseasePrevalence.diabetesTreatment | D11: =HealthIndicatorsOah!D11 -> % of people under treatment for diabetes | E11: Observation | G11: relatedto
A12: ="http://hl7.eu/fhir/ig/oah/StructureDefinition/"&LogicalModels!$A$7 -> http://hl7.eu/fhir/ig/oah/StructureDefinition/HealthIndicators | B12: http://hl7.eu/fhir/ig/oah/StructureDefinition/observation-health-measure-oah | C12: =HealthIndicatorsOah!A12 -> diseasePrevalence.noPhysicalActivity | D12: =HealthIndicatorsOah!D12 -> % of people not engaging in physical activity | E12: Observation | G12: relatedto
A13: ="http://hl7.eu/fhir/ig/oah/StructureDefinition/"&LogicalModels!$A$7 -> http://hl7.eu/fhir/ig/oah/StructureDefinition/HealthIndicators | B13: http://hl7.eu/fhir/ig/oah/StructureDefinition/observation-health-measure-oah | C13: =HealthIndicatorsOah!A13 -> diseasePrevalence.cvd | D13: =HealthIndicatorsOah!D13 -> % of people affected from CVD | E13: Observation | G13: relatedto
A14: ="http://hl7.eu/fhir/ig/oah/StructureDefinition/"&LogicalModels!$A$7 -> http://hl7.eu/fhir/ig/oah/StructureDefinition/HealthIndicators | B14: http://hl7.eu/fhir/ig/oah/StructureDefinition/observation-health-measure-oah | C14: =HealthIndicatorsOah!A14 -> diseasePrevalence.gastrointestinal | D14: =HealthIndicatorsOah!D14 -> % of people with Cases of Gastrointestinal diseases | E14: Observation | G14: relatedto
A15: ="http://hl7.eu/fhir/ig/oah/StructureDefinition/"&LogicalModels!$A$7 -> http://hl7.eu/fhir/ig/oah/StructureDefinition/HealthIndicators | B15: http://hl7.eu/fhir/ig/oah/StructureDefinition/observation-health-measure-oah | C15: =HealthIndicatorsOah!A15 -> diseasePrevalence.longTermDisease | D15: =HealthIndicatorsOah!D15 -> % of people with long-term disease | E15: Observation | G15: relatedto
... A64: ="http://hl7.eu/fhir/ig/oah/StructureDefinition/"&LogicalModels!$A$7 -> http://hl7.eu/fhir/ig/oah/StructureDefinition/HealthIndicators | B64: http://hl7.eu/fhir/ig/oah/StructureDefinition/observation-health-measure-oah | C64: =HealthIndicatorsOah!A64 -> hospitalization.avoidablePrimaryPrevention | D64: =HealthIndicatorsOah!D64 -> % of hospitalizations avoidable by primary prevention | E64: Observation | G64: relatedto

Sheet HealthIndicatorsOah
A1: Element | B1: Cardinality | C1: Datatype | D1: Short | E1: Definition
A2: diseasePrevalence | B2: 0..* | C2: Base | D2: Cases of disease prevalence | E2: Cases of disease prevalence per 100.000 inhabitants, per district, for each of the causes considered as relatable to the project
A3: diseasePrevalence.highBloodPression | B3: 0..* | C3: HealthMeasure | D3: % of people with high blood pressure (prevalence) | E3: =D3&" - Cases of disease prevalence per 100.000 inhabitants, per district, for each of the causes considered as relatable to the project" -> % of people with high blood pressure (prevalence) - Cases of disease prevalence per 100.000 inhabitants, per district, for each of the causes considered as relatable to the project
A4: diseasePrevalence.hypertension | B4: 0..* | C4: HealthMeasure | D4: % of people under treatment for hypertension | E4: =D4&" - Cases of disease prevalence per 100.000 inhabitants, per district, for each of the causes considered as relatable to the project" -> % of people under treatment for hypertension - Cases of disease prevalence per 100.000 inhabitants, per district, for each of the causes considered as relatable to the project
A5: diseasePrevalence.highBloodPressionTreatment | B5: 0..* | C5: HealthMeasure | D5: % of people under treatment for high blood pressure | E5: =D5&" - Cases of disease prevalence per 100.000 inhabitants, per district, for each of the causes considered as relatable to the project" -> % of people under treatment for high blood pressure - Cases of disease prevalence per 100.000 inhabitants, per district, for each of the causes considered as relatable to the project
A6: diseasePrevalence.obesity | B6: 0..* | C6: HealthMeasure | D6: % of people affected from obesity | E6: =D6&" - Cases of disease prevalence per 100.000 inhabitants, per district, for each of the causes considered as relatable to the project" -> % of people affected from obesity - Cases of disease prevalence per 100.000 inhabitants, per district, for each of the causes considered as relatable to the project
A7: diseasePrevalence.cholesterolemia190 | B7: 0..* | C7: HealthMeasure | D7: % of people with high total cholesterolemia (>=190 mg/dl) | E7: =D7&" - Cases of disease prevalence per 100.000 inhabitants, per district, for each of the causes considered as relatable to the project" -> % of people with high total cholesterolemia (>=190 mg/dl) - Cases of disease prevalence per 100.000 inhabitants, per district, for each of the causes considered as relatable to the project
A8: diseasePrevalence.hypercholesterolemiaTreatment | B8: 0..* | C8: HealthMeasure | D8: % of people under treatment for hypercholesterolemia | E8: =D8&" - Cases of disease prevalence per 100.000 inhabitants, per district, for each of the causes considered as relatable to the project" -> % of people under treatment for hypercholesterolemia - Cases of disease prevalence per 100.000 inhabitants, per district, for each of the causes considered as relatable to the project
A9: diseasePrevalence.cholesterolemia240 | B9: 0..* | C9: HealthMeasure | D9: % of people with high total cholesterolemia (>=240 mg/dl) | E9: =D9&" - Cases of disease prevalence per 100.000 inhabitants, per district, for each of the causes considered as relatable to the project" -> % of people with high total cholesterolemia (>=240 mg/dl) - Cases of disease prevalence per 100.000 inhabitants, per district, for each of the causes considered as relatable to the project
A10: diseasePrevalence.diabetes | B10: 0..* | C10: HealthMeasure | D10: % of people with high blood sugar/diabetes | E10: =D10&" - Cases of disease prevalence per 100.000 inhabitants, per district, for each of the causes considered as relatable to the project" -> % of people with high blood sugar/diabetes - Cases of disease prevalence per 100.000 inhabitants, per district, for each of the causes considered as relatable to the project
A11: diseasePrevalence.diabetesTreatment | B11: 0..* | C11: HealthMeasure | D11: % of people under treatment for diabetes | E11: =D11&" - Cases of disease prevalence per 100.000 inhabitants, per district, for each of the causes considered as relatable to the project" -> % of people under treatment for diabetes - Cases of disease prevalence per 100.000 inhabitants, per district, for each of the causes considered as relatable to the project
A12: diseasePrevalence.noPhysicalActivity | B12: 0..* | C12: HealthMeasure | D12: % of people not engaging in physical activity | E12: =D12&" - Cases of disease prevalence per 100.000 inhabitants, per district, for each of the causes considered as relatable to the project" -> % of people not engaging in physical activity - Cases of disease prevalence per 100.000 inhabitants, per district, for each of the causes considered as relatable to the project
A13: diseasePrevalence.cvd | B13: 0..* | C13: HealthMeasure | D13: % of people affected from CVD | E13: =D13&" - Cases of disease prevalence per 100.000 inhabitants, per district, for each of the causes considered as relatable to the project" -> % of people affected from CVD - Cases of disease prevalence per 100.000 inhabitants, per district, for each of the causes considered as relatable to the project
A14: diseasePrevalence.gastrointestinal | B14: 0..* | C14: HealthMeasure | D14: % of people with Cases of Gastrointestinal diseases | E14: =D14&" - Cases of disease prevalence per 100.000 inhabitants, per district, for each of the causes considered as relatable to the project" -> % of people with Cases of Gastrointestinal diseases - Cases of disease prevalence per 100.000 inhabitants, per district, for each of the causes considered as relatable to the project
... A32: diseasePrevalence.yersiniaEnterocolitica | B32: 0..* | C32: HealthMeasure | D32: % of people with Yersinia enterocolitica | E32: =D32&" - Cases of disease prevalence per 100.000 inhabitants, per district, for each of the causes considered as relatable to the project" -> % of people with Yersinia enterocolitica - Cases of disease prevalence per 100.000 inhabitants, per district, for each of the causes considered as relatable to the project
A33: causesOfDeath | B33: 0..* | C33: Base | D33: Cases of death | E33: Cases of death per 100.000 inhabitants, per district, for each of the causes considered as relatable to the project
A34: causesOfDeath.tbc | B34: 0..* | C34: HealthMeasure | D34: % of deaths due to TBC | E34: =D34&" - Cases per 100.000 inhabitants, per district, for each of the causes considered as relatable to the project" -> % of deaths due to TBC - Cases per 100.000 inhabitants, per district, for each of the causes considered as relatable to the project
A35: causesOfDeath.viralHepatitis | B35: 0..* | C35: HealthMeasure | D35: % of deaths due to Viral Hepatitis | E35: =D35&" - Cases per 100.000 inhabitants, per district, for each of the causes considered as relatable to the project" -> % of deaths due to Viral Hepatitis - Cases per 100.000 inhabitants, per district, for each of the causes considered as relatable to the project
A36: causesOfDeath.infectiveAndParasitic | B36: 0..* | C36: HealthMeasure | D36: % of deaths due to infective and parasitic diseases | E36: =D36&" - Cases per 100.000 inhabitants, per district, for each of the causes considered as relatable to the project" -> % of deaths due to infective and parasitic diseases - Cases per 100.000 inhabitants, per district, for each of the causes considered as relatable to the project
A37: causesOfDeath.bloodAndHematopoieticOrgans | B37: 0..* | C37: HealthMeasure | D37: % of deaths due to diseases of the blood and hematopoietic organs | E37: =D37&" - Cases per 100.000 inhabitants, per district, for each of the causes considered as relatable to the project" -> % of deaths due to diseases of the blood and hematopoietic organs - Cases per 100.000 inhabitants, per district, for each of the causes considered as relatable to the project
A38: causesOfDeath.diabetesMellitus | B38: 0..* | C38: HealthMeasure | D38: % of deaths due to Diabetes Mellitus | E38: =D38&" - Cases per 100.000 inhabitants, per district, for each of the causes considered as relatable to the project" -> % of deaths due to Diabetes Mellitus - Cases per 100.000 inhabitants, per district, for each of the causes considered as relatable to the project
A39: causesOfDeath.endocrineNutritionalMetabolic | B39: 0..* | C39: HealthMeasure | D39: % of deaths due to endocrine, nutritional and metabolic diseases | E39: =D39&" - Cases per 100.000 inhabitants, per district, for each of the causes considered as relatable to the project" -> % of deaths due to endocrine, nutritional and metabolic diseases - Cases per 100.000 inhabitants, per district, for each of the causes considered as relatable to the project
A40: causesOfDeath.ischemicHeart | B40: 0..* | C40: HealthMeasure | D40: % of deaths due to ischemic diseases of the heart | E40: =D40&" - Cases per 100.000 inhabitants, per district, for each of the causes considered as relatable to the project" -> % of deaths due to ischemic diseases of the heart - Cases per 100.000 inhabitants, per district, for each of the causes considered as relatable to the project
A41: causesOfDeath.otherHeart | B41: 0..* | C41: HealthMeasure | D41: % of deaths due to other diseases of the heart | E41: =D41&" - Cases per 100.000 inhabitants, per district, for each of the causes considered as relatable to the project" -> % of deaths due to other diseases of the heart - Cases per 100.000 inhabitants, per district, for each of the causes considered as relatable to the project
A42: causesOfDeath.otherCirculatorySystem | B42: 0..* | C42: HealthMeasure | D42: % of deaths due to other diseases of the circulatory system | E42: =D42&" - Cases per 100.000 inhabitants, per district, for each of the causes considered as relatable to the project" -> % of deaths due to other diseases of the circulatory system - Cases per 100.000 inhabitants, per district, for each of the causes considered as relatable to the project
A43: causesOfDeath.pneumonia | B43: 0..* | C43: HealthMeasure | D43: % of deaths due to Pneumonia | E43: =D43&" - Cases per 100.000 inhabitants, per district, for each of the causes considered as relatable to the project" -> % of deaths due to Pneumonia - Cases per 100.000 inhabitants, per district, for each of the causes considered as relatable to the project
A44: causesOfDeath.chronicLowerRespiratory | B44: 0..* | C44: HealthMeasure | D44: % of deaths due to chronic diseases of the lower respiratory tract | E44: =D44&" - Cases per 100.000 inhabitants, per district, for each of the causes considered as relatable to the project" -> % of deaths due to chronic diseases of the lower respiratory tract - Cases per 100.000 inhabitants, per district, for each of the causes considered as relatable to the project
A45: causesOfDeath.otherRespiratorySystem | B45: 0..* | C45: HealthMeasure | D45: % of deaths due to other diseases of the respiratory system | E45: =D45&" - Cases per 100.000 inhabitants, per district, for each of the causes considered as relatable to the project" -> % of deaths due to other diseases of the respiratory system - Cases per 100.000 inhabitants, per district, for each of the causes considered as relatable to the project
... A47: causesOfDeath.accidentalPoisoning | B47: 0..* | C47: HealthMeasure | D47: % of deaths due to accidental poisoning | E47: =D47&" - Cases per 100.000 inhabitants, per district, for each of the causes considered as relatable to the project" -> % of deaths due to accidental poisoning - Cases per 100.000 inhabitants, per district, for each of the causes considered as relatable to the project
A48: causesOfDeath.malignantTumor | B48: 0..* | C48: HealthMeasure | D48: % of deaths due to Malignant Tumors | E48: =D48&" - Cases per 100.000 inhabitants, per parish for each of the causes considered as relatable to the project" -> % of deaths due to Malignant Tumors - Cases per 100.000 inhabitants, per parish for each of the causes considered as relatable to the project
A49: causesOfDeath.healthcareSensitiveCauses | B49: 0..* | C49: HealthMeasure | D49: % of deaths due to Healthcare-Sensitive Causes | E49: =D49&" - Cases per 100.000 inhabitants, per parish for each of the causes considered as relatable to the project" -> % of deaths due to Healthcare-Sensitive Causes - Cases per 100.000 inhabitants, per parish for each of the causes considered as relatable to the project
A50: causesOfDeath.winterExcess | B50: 0..* | C50: HealthMeasure | D50: % of Excess Mortality in Winter | E50: =D50&" - Cases per 100.000 inhabitants, per parish for each of the causes considered as relatable to the project" -> % of Excess Mortality in Winter - Cases per 100.000 inhabitants, per parish for each of the causes considered as relatable to the project
A51: causesOfDeath.all | B51: 0..* | C51: HealthMeasure | D51: % of deaths due to all causes | E51: =D51&" - Cases per 100.000 inhabitants, per borough for each of the causes considered as relatable to the project" -> % of deaths due to all causes - Cases per 100.000 inhabitants, per borough for each of the causes considered as relatable to the project
A52: causesOfDeath.cancer | B52: 0..* | C52: HealthMeasure | D52: % of deaths due to cancer | E52: =D52&" - Cases per 100.000 inhabitants, per borough for each of the causes considered as relatable to the project" -> % of deaths due to cancer - Cases per 100.000 inhabitants, per borough for each of the causes considered as relatable to the project
A53: causesOfDeath.diabetes | B53: 0..* | C53: HealthMeasure | D53: % of deaths due to diabetes | E53: =D53&" - Cases per 100.000 inhabitants, per borough for each of the causes considered as relatable to the project" -> % of deaths due to diabetes - Cases per 100.000 inhabitants, per borough for each of the causes considered as relatable to the project
A54: causesOfDeath.cardiovascular | B54: 0..* | C54: HealthMeasure | D54: % of deaths due to cardiovascular disease | E54: =D54&" - Cases per 100.000 inhabitants, per borough for each of the causes considered as relatable to the project" -> % of deaths due to cardiovascular disease - Cases per 100.000 inhabitants, per borough for each of the causes considered as relatable to the project
A55: causesOfDeath.respiratory | B55: 0..* | C55: HealthMeasure | D55: % of deaths due to respiratory disease | E55: =D55&" - Cases per 100.000 inhabitants, per borough for each of the causes considered as relatable to the project" -> % of deaths due to respiratory disease - Cases per 100.000 inhabitants, per borough for each of the causes considered as relatable to the project
A56: causesOfDeath.COPDLungCancer | B56: 0..* | C56: HealthMeasure | D56: % of deaths due to COPD and lung cancer | E56: =D56&" - Cases per 100.000 inhabitants, per borough for each of the causes considered as relatable to the project" -> % of deaths due to COPD and lung cancer - Cases per 100.000 inhabitants, per borough for each of the causes considered as relatable to the project
A57: hospitalization | B57: 0..* | C57: HealthMeasure
A58: hospitalization.diabetesMellitus | B58: 0..* | C58: HealthMeasure | D58: % of hospitalizations due to Diabetes Mellitus | E58: % of hospitalizations due to Diabetes Mellitus (No. per 100,000 inhabitants)
...

Sheet IndicatorsOah2FHIR
A1: Group Source | B1: Group Target | C1: Source Code | D1: Source Display | E1: Target Code | F1: Target Display | G1: Equivalence | H1: Comment
A2: ="http://hl7.eu/fhir/ig/oah/StructureDefinition/"&LogicalModels!$A$2 -> http://hl7.eu/fhir/ig/oah/StructureDefinition/IndicatorsOah | B2: http://hl7.eu/fhir/ig/oah/StructureDefinition/observation-indicators-oah | C2: =IndicatorsOah!A2 -> biological | D2: =IndicatorsOah!D2 -> Key biological quality indicators | E2: Observation | G2: relatedto
A3: ="http://hl7.eu/fhir/ig/oah/StructureDefinition/"&LogicalModels!$A$2 -> http://hl7.eu/fhir/ig/oah/StructureDefinition/IndicatorsOah | B3: http://hl7.eu/fhir/ig/oah/StructureDefinition/observation-indicators-oah | C3: =IndicatorsOah!A3 -> biological.macroinvertebreates | D3: =IndicatorsOah!D3 -> Benthic Macroinvertebrates | E3: Observation | F3: ="" | G3: relatedto | H3: where Observation.code is 'macroinvertebreates'
A4: ="http://hl7.eu/fhir/ig/oah/StructureDefinition/"&LogicalModels!$A$2 -> http://hl7.eu/fhir/ig/oah/StructureDefinition/IndicatorsOah | B4: http://hl7.eu/fhir/ig/oah/StructureDefinition/observation-indicators-oah | C4: =IndicatorsOah!A4 -> biological.diatomes | D4: =IndicatorsOah!D4 -> Diatoms (microalgae/phytobenthos) | E4: Observation | G4: relatedto | H4: where Observation.code is 'diatomes'
A5: ="http://hl7.eu/fhir/ig/oah/StructureDefinition/"&LogicalModels!$A$2 -> http://hl7.eu/fhir/ig/oah/StructureDefinition/IndicatorsOah | B5: http://hl7.eu/fhir/ig/oah/StructureDefinition/observation-indicators-oah | C5: =IndicatorsOah!A5 -> biological.fishes | D5: =IndicatorsOah!D5 -> Fish | E5: Observation | G5: relatedto | H5: where Observation.code is 'fishes'
A6: ="http://hl7.eu/fhir/ig/oah/StructureDefinition/"&LogicalModels!$A$2 -> http://hl7.eu/fhir/ig/oah/StructureDefinition/IndicatorsOah | B6: http://hl7.eu/fhir/ig/oah/StructureDefinition/observation-with-component-oah | C6: =IndicatorsOah!A6 -> biological.macrophytes | D6: =IndicatorsOah!D6 -> Macrophytes (aquatic plants) | E6: Observation | G6: relatedto | H6: where Observation.code is 'macrophytes'. Multimple results are recorded for this indicator.
A7: ="http://hl7.eu/fhir/ig/oah/StructureDefinition/"&LogicalModels!$A$2 -> http://hl7.eu/fhir/ig/oah/StructureDefinition/IndicatorsOah | B7: http://hl7.eu/fhir/ig/oah/StructureDefinition/observation-with-component-oah | C7: =IndicatorsOah!A7 -> biological.riparianVegetation | D7: =IndicatorsOah!D7 -> Riparian vegetation | E7: Observation | G7: relatedto | H7: where Observation.code is 'riparianVegetation'.Multimple results are recorded for this indicator.
A8: ="http://hl7.eu/fhir/ig/oah/StructureDefinition/"&LogicalModels!$A$2 -> http://hl7.eu/fhir/ig/oah/StructureDefinition/IndicatorsOah | B8: http://hl7.eu/fhir/ig/oah/StructureDefinition/observation-indicators-oah | C8: =IndicatorsOah!A8 -> biological.microbiomes | D8: =IndicatorsOah!D8 -> Microbiomes/Biofilms | E8: Observation | G8: relatedto | H8: where Observation.code is 'microbiomes'
A9: ="http://hl7.eu/fhir/ig/oah/StructureDefinition/"&LogicalModels!$A$2 -> http://hl7.eu/fhir/ig/oah/StructureDefinition/IndicatorsOah | B9: http://hl7.eu/fhir/ig/oah/StructureDefinition/observation-indicators-oah | C9: =IndicatorsOah!A9 -> hydromorphological | D9: =IndicatorsOah!D9 -> Key hydromorphological quality indicators | E9: Observation | G9: relatedto
A10: ="http://hl7.eu/fhir/ig/oah/StructureDefinition/"&LogicalModels!$A$2 -> http://hl7.eu/fhir/ig/oah/StructureDefinition/IndicatorsOah | B10: http://hl7.eu/fhir/ig/oah/StructureDefinition/observation-indicators-oah | C10: =IndicatorsOah!A10 -> hydromorphological.morphology | D10: =IndicatorsOah!D10 -> Morphology of the streams | E10: Observation | G10: relatedto | H10: where Observation.code is 'morphology'
A11: ="http://hl7.eu/fhir/ig/oah/StructureDefinition/"&LogicalModels!$A$2 -> http://hl7.eu/fhir/ig/oah/StructureDefinition/IndicatorsOah | B11: http://hl7.eu/fhir/ig/oah/StructureDefinition/observation-indicators-oah | C11: =IndicatorsOah!A11 -> hydromorphological.hydrology | D11: =IndicatorsOah!D11 -> Hydrology of the stream | E11: Observation | G11: relatedto | H11: where Observation.code is 'hydrology'
A12: ="http://hl7.eu/fhir/ig/oah/StructureDefinition/"&LogicalModels!$A$2 -> http://hl7.eu/fhir/ig/oah/StructureDefinition/IndicatorsOah | B12: http://hl7.eu/fhir/ig/oah/StructureDefinition/observation-indicators-oah | C12: =IndicatorsOah!A12 -> hydromorphological.landUse | D12: =IndicatorsOah!D12 -> Land use in the margins | E12: Observation | G12: relatedto | H12: where Observation.code is 'landUse'
A13: ="http://hl7.eu/fhir/ig/oah/StructureDefinition/"&LogicalModels!$A$2 -> http://hl7.eu/fhir/ig/oah/StructureDefinition/IndicatorsOah | B13: http://hl7.eu/fhir/ig/oah/StructureDefinition/observation-indicators-oah | C13: =IndicatorsOah!A13 -> water | D13: =IndicatorsOah!D13 -> Key water quality indicators | E13: Observation | G13: relatedto
A14: ="http://hl7.eu/fhir/ig/oah/StructureDefinition/"&LogicalModels!$A$2 -> http://hl7.eu/fhir/ig/oah/StructureDefinition/IndicatorsOah | B14: http://hl7.eu/fhir/ig/oah/StructureDefinition/observation-indicators-oah | C14: =IndicatorsOah!A14 -> water.nutrients | D14: =IndicatorsOah!D14 -> Nutrients | E14: Observation | G14: relatedto | H14: where Observation.code is 'nutrients'
A15: ="http://hl7.eu/fhir/ig/oah/StructureDefinition/"&LogicalModels!$A$2 -> http://hl7.eu/fhir/ig/oah/StructureDefinition/IndicatorsOah | B15: http://hl7.eu/fhir/ig/oah/StructureDefinition/observation-indicators-oah | C15: =IndicatorsOah!A15 -> water.pH | D15: =IndicatorsOah!D15 -> pH | E15: Observation | G15: relatedto | H15: where Observation.code is 'pH'
A16: ="http://hl7.eu/fhir/ig/oah/StructureDefinition/"&LogicalModels!$A$2 -> http://hl7.eu/fhir/ig/oah/StructureDefinition/IndicatorsOah | B16: http://hl7.eu/fhir/ig/oah/StructureDefinition/observation-indicators-oah | C16: =IndicatorsOah!A16 -> water.dissolvedO2 | D16: =IndicatorsOah!D16 -> Dissolved O2 | E16: Observation | G16: relatedto | H16: where Observation.code is 'dissolvedO2'
A17: ="http://hl7.eu/fhir/ig/oah/StructureDefinition/"&LogicalModels!$A$2 -> http://hl7.eu/fhir/ig/oah/StructureDefinition/IndicatorsOah | B17: http://hl7.eu/fhir/ig/oah/StructureDefinition/observation-indicators-oah | C17: =IndicatorsOah!A17 -> water.waterTemperature | D17: =IndicatorsOah!D17 -> Water temperature | E17: Observation | G17: relatedto | H17: where Observation.code is 'waterTemperature'
A18: ="http://hl7.eu/fhir/ig/oah/StructureDefinition/"&LogicalModels!$A$2 -> http://hl7.eu/fhir/ig/oah/StructureDefinition/IndicatorsOah | B18: http://hl7.eu/fhir/ig/oah/StructureDefinition/observation-indicators-oah | C18: =IndicatorsOah!A18 -> water.tds | D18: =IndicatorsOah!D18 -> Total dissolved solids (TDS) | E18: Observation | G18: relatedto | H18: where Observation.code is 'tds'
A19: ="http://hl7.eu/fhir/ig/oah/StructureDefinition/"&LogicalModels!$A$2 -> http://hl7.eu/fhir/ig/oah/StructureDefinition/IndicatorsOah | B19: http://hl7.eu/fhir/ig/oah/StructureDefinition/observation-indicators-oah | C19: =IndicatorsOah!A19 -> water.tss | D19: =IndicatorsOah!D19 -> Total suspended solids (TSS) | E19: Observation | G19: relatedto | H19: where Observation.code is 'tss'
A20: ="http://hl7.eu/fhir/ig/oah/StructureDefinition/"&LogicalModels!$A$2 -> http://hl7.eu/fhir/ig/oah/StructureDefinition/IndicatorsOah | B20: http://hl7.eu/fhir/ig/oah/StructureDefinition/observation-indicators-oah | C20: =IndicatorsOah!A20 -> water.conductivity | D20: =IndicatorsOah!D20 -> Conductivity | E20: Observation | G20: relatedto | H20: where Observation.code is 'conductivity'
A21: ="http://hl7.eu/fhir/ig/oah/StructureDefinition/"&LogicalModels!$A$2 -> http://hl7.eu/fhir/ig/oah/StructureDefinition/IndicatorsOah | B21: http://hl7.eu/fhir/ig/oah/StructureDefinition/observation-indicators-oah | C21: =IndicatorsOah!A21 -> water.pharmaceuticals | D21: =IndicatorsOah!D21 -> Pharmaceuticals | E21: Observation | G21: relatedto | H21: where Observation.code is 'pharmaceuticals'
A22: ="http://hl7.eu/fhir/ig/oah/StructureDefinition/"&LogicalModels!$A$2 -> http://hl7.eu/fhir/ig/oah/StructureDefinition/IndicatorsOah | B22: http://hl7.eu/fhir/ig/oah/StructureDefinition/observation-indicators-oah | C22: =IndicatorsOah!A22 -> water.foam | D22: =IndicatorsOah!D22 -> Foam/colour/smell | E22: Observation | G22: relatedto | H22: where Observation.code is 'foam'
A23: ="http://hl7.eu/fhir/ig/oah/StructureDefinition/"&LogicalModels!$A$2 -> http://hl7.eu/fhir/ig/oah/StructureDefinition/IndicatorsOah | B23: http://hl7.eu/fhir/ig/oah/StructureDefinition/observation-indicators-oah | C23: =IndicatorsOah!A23 -> water.coliforms | D23: =IndicatorsOah!D23 -> Coliforms | E23: Observation | G23: relatedto | H23: where Observation.code is 'coliforms'
A24: ="http://hl7.eu/fhir/ig/oah/StructureDefinition/"&LogicalModels!$A$2 -> http://hl7.eu/fhir/ig/oah/StructureDefinition/IndicatorsOah | B24: http://hl7.eu/fhir/ig/oah/StructureDefinition/observation-indicators-oah | C24: =IndicatorsOah!A24 -> bioRisk | D24: =IndicatorsOah!D24 -> Biological indicators of health risks | E24: Observation | G24: relatedto
A25: ="http://hl7.eu/fhir/ig/oah/StructureDefinition/"&LogicalModels!$A$2 -> http://hl7.eu/fhir/ig/oah/StructureDefinition/IndicatorsOah | B25: http://hl7.eu/fhir/ig/oah/StructureDefinition/observation-indicators-oah | C25: =IndicatorsOah!A25 -> bioRisk.diptera | D25: =IndicatorsOah!D25 -> Diptera | E25: Observation | G25: relatedto | H25: where Observation.code is 'diptera'
A26: ="http://hl7.eu/fhir/ig/oah/StructureDefinition/"&LogicalModels!$A$2 -> http://hl7.eu/fhir/ig/oah/StructureDefinition/IndicatorsOah | B26: http://hl7.eu/fhir/ig/oah/StructureDefinition/observation-indicators-oah | C26: =IndicatorsOah!A26 -> bioRisk.ticks | D26: =IndicatorsOah!D26 -> Ticks | E26: Observation | G26: relatedto | H26: where Observation.code is 'ticks'
A27: ="http://hl7.eu/fhir/ig/oah/StructureDefinition/"&LogicalModels!$A$2 -> http://hl7.eu/fhir/ig/oah/StructureDefinition/IndicatorsOah | B27: http://hl7.eu/fhir/ig/oah/StructureDefinition/observation-indicators-oah | C27: =IndicatorsOah!A27 -> bioRisk.invasiveOrganisms | D27: =IndicatorsOah!D27 -> Invasive invertebrate, plants and fish | E27: Observation | G27: relatedto | H27: where Observation.code is 'invasiveOrganisms'
A28: ="http://hl7.eu/fhir/ig/oah/StructureDefinition/"&LogicalModels!$A$2 -> http://hl7.eu/fhir/ig/oah/StructureDefinition/IndicatorsOah | B28: http://hl7.eu/fhir/ig/oah/StructureDefinition/observation-indicators-oah | C28: =IndicatorsOah!A28 -> bioRisk.birds | D28: =IndicatorsOah!D28 -> Birds | E28: Observation | G28: relatedto | H28: where Observation.code is 'birds'
A29: ="http://hl7.eu/fhir/ig/oah/StructureDefinition/"&LogicalModels!$A$2 -> http://hl7.eu/fhir/ig/oah/StructureDefinition/IndicatorsOah | B29: http://hl7.eu/fhir/ig/oah/StructureDefinition/observation-indicators-oah | C29: =IndicatorsOah!A29 -> bioRisk.diatomTratology | D29: =IndicatorsOah!D29 -> Diatom teratology | E29: Observation | G29: relatedto | H29: where Observation.code is 'diatomTratology'
A30: ="http://hl7.eu/fhir/ig/oah/StructureDefinition/"&LogicalModels!$A$2 -> http://hl7.eu/fhir/ig/oah/StructureDefinition/IndicatorsOah | B30: http://hl7.eu/fhir/ig/oah/StructureDefinition/observation-indicators-oah | C30: =IndicatorsOah!A30 -> bioRisk.fish | D30: =IndicatorsOah!D30 -> Fish | E30: Observation | G30: relatedto | H30: where Observation.code is 'fish'
A31: ="http://hl7.eu/fhir/ig/oah/StructureDefinition/"&LogicalModels!$A$2 -> http://hl7.eu/fhir/ig/oah/StructureDefinition/IndicatorsOah | B31: http://hl7.eu/fhir/ig/oah/StructureDefinition/observation-indicators-oah | C31: =IndicatorsOah!A31 -> bioRisk.amphibians | D31: =IndicatorsOah!D31 -> Amphibians | E31: Observation | G31: relatedto | H31: where Observation.code is 'amphibians'
A32: ="http://hl7.eu/fhir/ig/oah/StructureDefinition/"&LogicalModels!$A$2 -> http://hl7.eu/fhir/ig/oah/StructureDefinition/IndicatorsOah | B32: http://hl7.eu/fhir/ig/oah/StructureDefinition/observation-indicators-oah | C32: =IndicatorsOah!A32 -> remote | D32: =IndicatorsOah!D32 -> Remote sensing indices | E32: Observation | G32: relatedto | H32: where Observation.code is 'amphibians'
A33: ="http://hl7.eu/fhir/ig/oah/StructureDefinition/"&LogicalModels!$A$2 -> http://hl7.eu/fhir/ig/oah/StructureDefinition/IndicatorsOah | B33: http://hl7.eu/fhir/ig/oah/StructureDefinition/observation-indicators-oah | C33: =IndicatorsOah!A33 -> remote.ndci | D33: =IndicatorsOah!D33 -> Normalized Difference Chlorophyll Index (NDCI) | E33: Observation | G33: relatedto | H33: where Observation.code is 'amphibians'
A34: ="http://hl7.eu/fhir/ig/oah/StructureDefinition/"&LogicalModels!$A$2 -> http://hl7.eu/fhir/ig/oah/StructureDefinition/IndicatorsOah | B34: http://hl7.eu/fhir/ig/oah/StructureDefinition/observation-indicators-oah | C34: =IndicatorsOah!A34 -> remote.mci | D34: =IndicatorsOah!D34 -> Maximum Chlorophyll Index (MCI) | E34: Observation | G34: relatedto | H34: where Observation.code is 'amphibians'
A35: ="http://hl7.eu/fhir/ig/oah/StructureDefinition/"&LogicalModels!$A$2 -> http://hl7.eu/fhir/ig/oah/StructureDefinition/IndicatorsOah | B35: http://hl7.eu/fhir/ig/oah/StructureDefinition/observation-indicators-oah | C35: =IndicatorsOah!A35 -> remote.bwdrvi | D35: =IndicatorsOah!D35 -> Blue Wide Dynamic Range Vegetation Index (BWDRVI) | E35: Observation | G35: relatedto | H35: where Observation.code is 'amphibians'
A36: ="http://hl7.eu/fhir/ig/oah/StructureDefinition/"&LogicalModels!$A$2 -> http://hl7.eu/fhir/ig/oah/StructureDefinition/IndicatorsOah | B36: http://hl7.eu/fhir/ig/oah/StructureDefinition/observation-indicators-oah | C36: =IndicatorsOah!A36 -> remote.evi | D36: =IndicatorsOah!D36 -> Enhanced Vegetation Index (EVI) | E36: Observation | G36: relatedto | H36: where Observation.code is 'amphibians'
B37: http://hl7.eu/fhir/ig/oah/StructureDefinition/observation-indicators-oah | C37: =IndicatorsOah!A37 -> remote.evi2 | D37: =IndicatorsOah!D37 -> Enhanced Vegetation Index 2 (EVI2) | E37: Observation | G37: relatedto | H37: where Observation.code is 'amphibians'
A38: ="http://hl7.eu/fhir/ig/oah/StructureDefinition/"&LogicalModels!$A$2 -> http://hl7.eu/fhir/ig/oah/StructureDefinition/IndicatorsOah | B38: http://hl7.eu/fhir/ig/oah/StructureDefinition/observation-indicators-oah | C38: =IndicatorsOah!A38 -> remote.ndvi | D38: =IndicatorsOah!D38 -> Normalized Difference Vegetation Index (NDVI) | E38: Observation | G38: relatedto | H38: where Observation.code is 'amphibians'
B39: http://hl7.eu/fhir/ig/oah/StructureDefinition/observation-indicators-oah | C39: =IndicatorsOah!A39 -> remote.mndvi | D39: =IndicatorsOah!D39 -> Modified Normalized Difference Vegetation Index (mNDVI) | E39: Observation | G39: relatedto | H39: where Observation.code is 'amphibians'
A40: ="http://hl7.eu/fhir/ig/oah/StructureDefinition/"&LogicalModels!$A$2 -> http://hl7.eu/fhir/ig/oah/StructureDefinition/IndicatorsOah | B40: http://hl7.eu/fhir/ig/oah/StructureDefinition/observation-indicators-oah | C40: =IndicatorsOah!A40 -> remote.ndwi | D40: =IndicatorsOah!D40 -> Normalized Difference Water Index (NDWI) | E40: Observation | G40: relatedto | H40: where Observation.code is 'amphibians'
...

Sheet IndicatorsOah
A1: Element | B1: Cardinality | C1: Datatype | D1: Short | E1: Definition
A2: biological | B2: 0..1 | C2: Base | D2: Key biological quality indicators | E2: Biological indicators of health risk . These are the indicators that were considered useful to test the links between aquatic ecosystem health and human well-being in the scope of the OneAquaHeath project
A3: biological.macroinvertebreates | B3: 0..* | C3: SimpleIndicator | D3: Benthic Macroinvertebrates | E3: Benthic Macroinvertebrates measure: e.g. number of snails in the sample
A4: biological.diatomes | B4: 0..* | C4: SimpleIndicator | D4: Diatoms (microalgae/phytobenthos) | E4: Diatoms (microalgae/phytobenthos) measures e.g. number of diatoma vulgaris in the sample
A5: biological.fishes | B5: 0..* | C5: SimpleIndicator | D5: Fish | E5: Fish related measures perfomed : e.g. number of carps in the sample
A6: biological.macrophytes | B6: 0..* | C6: StructuredIndicator | D6: Macrophytes (aquatic plants) | E6: Macrophytes (aquatic plants) related measures.
A7: biological.riparianVegetation | B7: 0..* | C7: StructuredIndicator | D7: Riparian vegetation | E7: Riparian vegetation related measures.
A8: biological.microbiomes | B8: 0..* | C8: Base | D8: Microbiomes/Biofilms | E8: Microbiomes/Biofilms
A9: hydromorphological | B9: 0..1 | C9: Base | D9: Key hydromorphological quality indicators | E9: The hydromorphological characteristics include the type and diversity of aquatic habitats, substrate of the bottom and margins, flow type, size of the rivers, land use in the margins, existence of barriers, or other artificial structures and land use in the margins. Those characteristics influence the river continuum, the habitats available for the aquatic biota, the species migration and the sediments, water flow and energy transferences over a river basin
A10: hydromorphological.morphology | B10: 0..* | C10: Base | D10: Morphology of the streams | E10: Morphology of the streams – habitat, shape of the channel and valley, substrate in the channel and margins
A11: hydromorphological.hydrology | B11: 0..* | C11: Base | D11: Hydrology of the stream | E11: Hydrology of the stream – flow type, diversity of flow types, longitudinal connectivity, runoff
A12: hydromorphological.landUse | B12: 0..* | C12: Base | D12: Land use in the margins | E12: Land use in the margins
... A62: remote.vibi | B62: 0..* | C62: Base | D62: Vegetation Index Built-up Index (VIBI) | E62: Combines vegetation and built-up indices for urban analysis

Sheet HealthMeasureOah2FHIR
A1: Group Source | B1: Group Target | C1: Source Code | D1: Source Display | E1: Target Code | F1: Target Display | G1: Equivalence | H1: Comment
A2: ="http://hl7.eu/fhir/ig/oah/StructureDefinition/"&LogicalModels!$A$8 -> http://hl7.eu/fhir/ig/oah/StructureDefinition/HealthMeasure | B2: http://hl7.eu/fhir/ig/oah/StructureDefinition/observation-health-measure-oah | C2: =HealthMeasureOah!A2 -> site | D2: =HealthMeasureOah!D2 -> Sampling Site | E2: Observation.subject | G2: relatedto | H2: This filed is realized by the subject and the specimen elements
A3: ="http://hl7.eu/fhir/ig/oah/StructureDefinition/"&LogicalModels!$A$8 -> http://hl7.eu/fhir/ig/oah/StructureDefinition/HealthMeasure | B3: http://hl7.eu/fhir/ig/oah/StructureDefinition/observation-health-measure-oah | C3: =HealthMeasureOah!A3 -> site.identifier | D3: =HealthMeasureOah!D3 -> Site identifier | E3: Observation.subject | G3: relatedto
A4: ="http://hl7.eu/fhir/ig/oah/StructureDefinition/"&LogicalModels!$A$8 -> http://hl7.eu/fhir/ig/oah/StructureDefinition/HealthMeasure | B4: http://hl7.eu/fhir/ig/oah/StructureDefinition/observation-health-measure-oah | C4: =HealthMeasureOah!A4 -> site.name | D4: =HealthMeasureOah!D4 -> Site Name | E4: Observation.subject | F4: ="" | G4: relatedto
A5: ="http://hl7.eu/fhir/ig/oah/StructureDefinition/"&LogicalModels!$A$8 -> http://hl7.eu/fhir/ig/oah/StructureDefinition/HealthMeasure | B5: http://hl7.eu/fhir/ig/oah/StructureDefinition/observation-health-measure-oah | C5: =HealthMeasureOah!A5 -> site.gps | D5: =HealthMeasureOah!D5 -> GPS | E5: Observation.subject | F5: ="" | G5: relatedto
A6: ="http://hl7.eu/fhir/ig/oah/StructureDefinition/"&LogicalModels!$A$8 -> http://hl7.eu/fhir/ig/oah/StructureDefinition/HealthMeasure | B6: http://hl7.eu/fhir/ig/oah/StructureDefinition/observation-health-measure-oah | C6: =HealthMeasureOah!A6 -> site.characteristics | D6: =HealthMeasureOah!D6 -> Characteristics | E6: Observation.subject | F6: ="" | G6: relatedto
A7: ="http://hl7.eu/fhir/ig/oah/StructureDefinition/"&LogicalModels!$A$8 -> http://hl7.eu/fhir/ig/oah/StructureDefinition/HealthMeasure | B7: http://hl7.eu/fhir/ig/oah/StructureDefinition/observation-health-measure-oah | C7: =HealthMeasureOah!A7 -> dateOrPeriod[x] | D7: =HealthMeasureOah!D7 -> Measure Date or Period | E7: Observation.effective[x] | G7: equivalent | H7: It could be a Person or an Organization
A8: ="http://hl7.eu/fhir/ig/oah/StructureDefinition/"&LogicalModels!$A$8 -> http://hl7.eu/fhir/ig/oah/StructureDefinition/HealthMeasure | B8: http://hl7.eu/fhir/ig/oah/StructureDefinition/observation-health-measure-oah | C8: =HealthMeasureOah!A8 -> perfomer[x] | D8: =HealthMeasureOah!D8 -> Performer | E8: Observation.performer[x] | G8: equivalent
A9: ="http://hl7.eu/fhir/ig/oah/StructureDefinition/"&LogicalModels!$A$8 -> http://hl7.eu/fhir/ig/oah/StructureDefinition/HealthMeasure | B9: http://hl7.eu/fhir/ig/oah/StructureDefinition/observation-health-measure-oah | C9: =HealthMeasureOah!A9 -> type | D9: =HealthMeasureOah!D9 -> What is measured | E9: Observation.code | G9: equivalent
A10: ="http://hl7.eu/fhir/ig/oah/StructureDefinition/"&LogicalModels!$A$8 -> http://hl7.eu/fhir/ig/oah/StructureDefinition/HealthMeasure | B10: http://hl7.eu/fhir/ig/oah/StructureDefinition/observation-health-measure-oah | C10: =HealthMeasureOah!A10 -> result[x] | D10: =HealthMeasureOah!D10 -> Result | E10: Observation.value[x] | G10: equivalent
A11: ="http://hl7.eu/fhir/ig/oah/StructureDefinition/"&LogicalModels!$A$8 -> http://hl7.eu/fhir/ig/oah/StructureDefinition/HealthMeasure | B11: http://hl7.eu/fhir/ig/oah/StructureDefinition/observation-health-measure-oah | C11: =HealthMeasureOah!A11 -> cohort | D11: =HealthMeasureOah!D11 -> Cohort | E11: Observation.focus | G11: relatedto
A12: ="http://hl7.eu/fhir/ig/oah/StructureDefinition/"&LogicalModels!$A$8 -> http://hl7.eu/fhir/ig/oah/StructureDefinition/HealthMeasure | B12: http://hl7.eu/fhir/ig/oah/StructureDefinition/group-oah | C12: =HealthMeasureOah!A11 -> cohort | D12: =HealthMeasureOah!D11 -> Cohort | E12: Observation.focus | G12: equivalent

Sheet HealthMeasureOah
A1: Element | B1: Cardinality | C1: Datatype | D1: Short | E1: Definition
A2: site | B2: 1..1 | C2: Base | D2: Sampling Site | E2: Sampling Site
A3: site.identifier | B3: 1..* | C3: Base | D3: Site identifier | E3: Site identifier
A4: site.name | B4: 1..* | C4: Base | D4: Site Name | E4: Site Name
A5: site.gps | B5: 0..1 | C5: Base | D5: GPS | E5: GPS
A6: site.characteristics | B6: 0..* | C6: Base | D6: Characteristics | E6: Characteristics
A7: dateOrPeriod[x] | B7: 1..1 | C7: dateTime or Period | D7: Measure Date or Period | E7: Measure Date or Period
A8: perfomer[x] | B8: 0..* | C8: PractitionerRole or Organization | D8: Performer | E8: Performer
A9: type | B9: 1..1 | C9: CodeableConcept | D9: What is measured | E9: Type of indicator : e.g. % of people with Giarda
A10: result[x] | B10: 1..1 | C10: CodeableConcept or Quantity | D10: Result | E10: Result of the observation: it could be a single value or a set of results
A11: cohort | B11: 1..1 | C11: Group | D11: Cohort | E11: Group of people who share a common characteristic.

Sheet SimpleIndicatorOah2FHIR
A1: Group Source | B1: Group Target | C1: Source Code | D1: Source Display | E1: Target Code | F1: Target Display | G1: Equivalence | H1: Comment
A2: ="http://hl7.eu/fhir/ig/oah/StructureDefinition/"&LogicalModels!$A$3 -> http://hl7.eu/fhir/ig/oah/StructureDefinition/SimpleIndicator | B2: http://hl7.eu/fhir/ig/oah/StructureDefinition/observation-indicators-oah | C2: =SimpleIndicatorOah!A2 -> sampleDetails | D2: =SimpleIndicatorOah!D2 -> Sample | E2: Observation | G2: relatedto | H2: This filed is realized by the subject and the specimen elements
A3: ="http://hl7.eu/fhir/ig/oah/StructureDefinition/"&LogicalModels!$A$3 -> http://hl7.eu/fhir/ig/oah/StructureDefinition/SimpleIndicator | B3: http://hl7.eu/fhir/ig/oah/StructureDefinition/observation-indicators-oah | C3: =SimpleIndicatorOah!A2 -> sampleDetails | D3: =SimpleIndicatorOah!D2 -> Sample | E3: Observation.subject | G3: relatedto
A4: ="http://hl7.eu/fhir/ig/oah/StructureDefinition/"&LogicalModels!$A$3 -> http://hl7.eu/fhir/ig/oah/StructureDefinition/SimpleIndicator | B4: http://hl7.eu/fhir/ig/oah/StructureDefinition/observation-indicators-oah | C4: =SimpleIndicatorOah!A2 -> sampleDetails | D4: =SimpleIndicatorOah!D2 -> Sample | E4: Observation.specimen | F4: ="" | G4: relatedto
A5: ="http://hl7.eu/fhir/ig/oah/StructureDefinition/"&LogicalModels!$A$3 -> http://hl7.eu/fhir/ig/oah/StructureDefinition/SimpleIndicator | B5: http://hl7.eu/fhir/ig/oah/StructureDefinition/observation-indicators-oah | C5: =SimpleIndicatorOah!A3 -> type | D5: =SimpleIndicatorOah!D3 -> What is measured | E5: Observation.code | F5: ="" | G5: equivalent
A6: ="http://hl7.eu/fhir/ig/oah/StructureDefinition/"&LogicalModels!$A$3 -> http://hl7.eu/fhir/ig/oah/StructureDefinition/SimpleIndicator | B6: http://hl7.eu/fhir/ig/oah/StructureDefinition/observation-indicators-oah | C6: =SimpleIndicatorOah!A4 -> date | D6: =SimpleIndicatorOah!D4 -> Observation date | E6: Observation.effectiveDateTime | G6: equivalent
A7: ="http://hl7.eu/fhir/ig/oah/StructureDefinition/"&LogicalModels!$A$3 -> http://hl7.eu/fhir/ig/oah/StructureDefinition/SimpleIndicator | B7: http://hl7.eu/fhir/ig/oah/StructureDefinition/observation-indicators-oah | C7: =SimpleIndicatorOah!A5 -> performer[x] | D7: =SimpleIndicatorOah!D5 -> Who made the measure | E7: Observation.performer[x] | G7: equivalent | H7: It could be a Person or an Organization
A8: ="http://hl7.eu/fhir/ig/oah/StructureDefinition/"&LogicalModels!$A$3 -> http://hl7.eu/fhir/ig/oah/StructureDefinition/SimpleIndicator | B8: http://hl7.eu/fhir/ig/oah/StructureDefinition/observation-indicators-oah | C8: =SimpleIndicatorOah!A6 -> result[x] | D8: =SimpleIndicatorOah!D6 -> Result | E8: Observation.value[x] | G8: equivalent

Sheet SimpleIndicatorOah
A1: Element | B1: Cardinality | C1: Datatype | D1: Short | E1: Definition
A2: sampleDetails | B2: 1..1 | C2: Sample | D2: Sample | E2: Information about the sample used for this measure
A3: type | B3: 1..1 | C3: CodeableConcept | D3: What is measured | E3: Type of indicator : e.g. number of mosquito in the sample
A4: date | B4: 1..* | C4: dateTime | D4: Observation date | E4: Observation date
A5: performer[x] | B5: 1..* | C5: PractitionerRole or Organization | D5: Who made the measure | E5: Who made the measure
A6: result[x] | B6: 1..1 | C6: CodeableConcept or Quantity | D6: Result | E6: Result of the observation: it could be a single value or a set of results

Sheet StructuredIndicatorOah2FHIR
A1: Group Source | B1: Group Target | C1: Source Code | D1: Source Display | E1: Target Code | F1: Target Display | G1: Equivalence | H1: Comment
A2: ="http://hl7.eu/fhir/ig/oah/StructureDefinition/"&LogicalModels!$A$4 -> http://hl7.eu/fhir/ig/oah/StructureDefinition/StructuredIndicator | B2: http://hl7.eu/fhir/ig/oah/StructureDefinition/observation-with-component-oah | C2: =StructuredIndicatorOah!A2 -> sampleDetails | D2: =StructuredIndicatorOah!D2 -> Sample | E2: Observation | G2: relatedto | H2: This filed is realized by the subject and the specimen elements
A3: ="http://hl7.eu/fhir/ig/oah/StructureDefinition/"&LogicalModels!$A$4 -> http://hl7.eu/fhir/ig/oah/StructureDefinition/StructuredIndicator | B3: http://hl7.eu/fhir/ig/oah/StructureDefinition/observation-with-component-oah | C3: =StructuredIndicatorOah!A2 -> sampleDetails | D3: =StructuredIndicatorOah!D2 -> Sample | E3: Observation.subject | G3: relatedto
A4: ="http://hl7.eu/fhir/ig/oah/StructureDefinition/"&LogicalModels!$A$4 -> http://hl7.eu/fhir/ig/oah/StructureDefinition/StructuredIndicator | B4: http://hl7.eu/fhir/ig/oah/StructureDefinition/observation-with-component-oah | C4: =StructuredIndicatorOah!A2 -> sampleDetails | D4: =StructuredIndicatorOah!D2 -> Sample | E4: Observation.specimen | F4: ="" | G4: relatedto
A5: ="http://hl7.eu/fhir/ig/oah/StructureDefinition/"&LogicalModels!$A$4 -> http://hl7.eu/fhir/ig/oah/StructureDefinition/StructuredIndicator | B5: http://hl7.eu/fhir/ig/oah/StructureDefinition/observation-with-component-oah | C5: =StructuredIndicatorOah!A3 -> type | D5: =StructuredIndicatorOah!D3 -> What is measured | E5: Observation.code | F5: ="" | G5: equivalent
A6: ="http://hl7.eu/fhir/ig/oah/StructureDefinition/"&LogicalModels!$A$4 -> http://hl7.eu/fhir/ig/oah/StructureDefinition/StructuredIndicator | B6: http://hl7.eu/fhir/ig/oah/StructureDefinition/observation-with-component-oah | C6: =StructuredIndicatorOah!A4 -> date | D6: =StructuredIndicatorOah!D4 -> Observation date | E6: Observation.effectiveDateTime | G6: equivalent
A7: ="http://hl7.eu/fhir/ig/oah/StructureDefinition/"&LogicalModels!$A$4 -> http://hl7.eu/fhir/ig/oah/StructureDefinition/StructuredIndicator | B7: http://hl7.eu/fhir/ig/oah/StructureDefinition/observation-with-component-oah | C7: =StructuredIndicatorOah!A5 -> performer[x] | D7: =StructuredIndicatorOah!D5 -> Who made the measure | E7: Observation.performer[x] | G7: equivalent | H7: It could be a Person or an Organization
A8: ="http://hl7.eu/fhir/ig/oah/StructureDefinition/"&LogicalModels!$A$4 -> http://hl7.eu/fhir/ig/oah/StructureDefinition/StructuredIndicator | B8: http://hl7.eu/fhir/ig/oah/StructureDefinition/observation-with-component-oah | C8: =StructuredIndicatorOah!A6 -> component | D8: =StructuredIndicatorOah!D6 -> Component | E8: Observation.component | G8: relatedto
A9: ="http://hl7.eu/fhir/ig/oah/StructureDefinition/"&LogicalModels!$A$4 -> http://hl7.eu/fhir/ig/oah/StructureDefinition/StructuredIndicator | B9: http://hl7.eu/fhir/ig/oah/StructureDefinition/observation-with-component-oah | C9: =StructuredIndicatorOah!A7 -> component.type | D9: =StructuredIndicatorOah!D7 -> What is measured | E9: Observation.component.code | G9: equivalent
A10: ="http://hl7.eu/fhir/ig/oah/StructureDefinition/"&LogicalModels!$A$4 -> http://hl7.eu/fhir/ig/oah/StructureDefinition/StructuredIndicator | B10: http://hl7.eu/fhir/ig/oah/StructureDefinition/observation-with-component-oah | C10: =StructuredIndicatorOah!A8 -> component.result[x] | D10: =StructuredIndicatorOah!D8 -> Result | E10: Observation.component.value[x] | G10: equivalent

Sheet StructuredIndicatorOah
A1: Element | B1: Cardinality | C1: Datatype | D1: Short | E1: Definition
A2: sampleDetails | B2: 1..1 | C2: Sample | D2: Sample | E2: Information about the sample used for this measure
A3: type | B3: 1..1 | C3: CodeableConcept | D3: What is measured | E3: Type of indicator : e.g. number of mosquito in the sample
A4: date | B4: 1..* | C4: dateTime | D4: Observation date | E4: Observation date
A5: performer[x] | B5: 1..* | C5: PractitionerRole or Organization | D5: Who made the measure | E5: Who made the measure
A6: component | B6: 1..* | C6: Base | D6: Component | E6: Set of results defining this indicator
A7: component.type | B7: 1..1 | C7: CodeableConcept | D7: What is measured | E7: Type of indicator : e.g. presence of liverworts
A8: component.result[x] | B8: 1..1 | C8: CodeableConcept or Quantity or string | D8: Result | E8: Result of the set of observation: it could be a single value or a set of results

Sheet SampleOah2FHIR
A1: Group Source | B1: Group Target | C1: Source Code | D1: Source Display | E1: Target Code | F1: Target Display | G1: Equivalence | H1: Comment
A2: ="http://hl7.eu/fhir/ig/oah/StructureDefinition/"&LogicalModels!$A$5 -> http://hl7.eu/fhir/ig/oah/StructureDefinition/Sample | B2: http://hl7.eu/fhir/ig/oah/StructureDefinition/specimen-oah | C2: =SampleOah!A2 -> site | D2: =SampleOah!D2 -> Sampling Site | E2: Specimen.subject | G2: relatedto | H2: if Specimen is used
A3: ="http://hl7.eu/fhir/ig/oah/StructureDefinition/"&LogicalModels!$A$5 -> http://hl7.eu/fhir/ig/oah/StructureDefinition/Sample | B3: http://hl7.eu/fhir/ig/oah/StructureDefinition/observation-indicators-oah | C3: =SampleOah!A2 -> site | D3: =SampleOah!D2 -> Sampling Site | E3: Observation.subject | G3: relatedto
A4: ="http://hl7.eu/fhir/ig/oah/StructureDefinition/"&LogicalModels!$A$5 -> http://hl7.eu/fhir/ig/oah/StructureDefinition/Sample | B4: http://hl7.eu/fhir/ig/oah/StructureDefinition/specimen-oah | C4: =SampleOah!A6 -> site.characteristics | D4: =SampleOah!D6 -> Characteristics | E4: Specimen | G4: unmatched
A5: ="http://hl7.eu/fhir/ig/oah/StructureDefinition/"&LogicalModels!$A$5 -> http://hl7.eu/fhir/ig/oah/StructureDefinition/Sample | B5: http://hl7.eu/fhir/ig/oah/StructureDefinition/specimen-oah | C5: =SampleOah!A8 -> dateOfSampling | D5: =SampleOah!D8 -> Date of Sample | E5: Specimen.collection.collectedDateTime | G5: equivalent
A6: ="http://hl7.eu/fhir/ig/oah/StructureDefinition/"&LogicalModels!$A$5 -> http://hl7.eu/fhir/ig/oah/StructureDefinition/Sample | B6: http://hl7.eu/fhir/ig/oah/StructureDefinition/specimen-oah | C6: =SampleOah!A9 -> perfomer[x] | D6: =SampleOah!D9 -> Performer | E6: Specimen.collection.collector | G6: equivalent
A7: ="http://hl7.eu/fhir/ig/oah/StructureDefinition/"&LogicalModels!$A$5 -> http://hl7.eu/fhir/ig/oah/StructureDefinition/Sample | B7: http://hl7.eu/fhir/ig/oah/StructureDefinition/location-oah | C7: =SampleOah!A2 -> site | D7: =SampleOah!D2 -> Sampling Site | E7: Location | G7: relatedto
A8: ="http://hl7.eu/fhir/ig/oah/StructureDefinition/"&LogicalModels!$A$5 -> http://hl7.eu/fhir/ig/oah/StructureDefinition/Sample | B8: http://hl7.eu/fhir/ig/oah/StructureDefinition/location-oah | C8: =SampleOah!A3 -> site.identifier | D8: =SampleOah!D3 -> Site identifier | E8: Location.identifier | G8: equivalent
A9: ="http://hl7.eu/fhir/ig/oah/StructureDefinition/"&LogicalModels!$A$5 -> http://hl7.eu/fhir/ig/oah/StructureDefinition/Sample | B9: http://hl7.eu/fhir/ig/oah/StructureDefinition/location-oah | C9: =SampleOah!A4 -> site.name | D9: =SampleOah!D4 -> Site Name | E9: Location.name | G9: equivalent
A10: ="http://hl7.eu/fhir/ig/oah/StructureDefinition/"&LogicalModels!$A$5 -> http://hl7.eu/fhir/ig/oah/StructureDefinition/Sample | B10: http://hl7.eu/fhir/ig/oah/StructureDefinition/location-oah | C10: =SampleOah!A5 -> site.gps | D10: =SampleOah!D5 -> GPS | E10: Location.position | G10: equivalent
A11: ="http://hl7.eu/fhir/ig/oah/StructureDefinition/"&LogicalModels!$A$5 -> http://hl7.eu/fhir/ig/oah/StructureDefinition/Sample | B11: http://hl7.eu/fhir/ig/oah/StructureDefinition/location-oah | C11: =SampleOah!A6 -> site.characteristics | D11: =SampleOah!D6 -> Characteristics | E11: Location | G11: unmatched
A12: ="http://hl7.eu/fhir/ig/oah/StructureDefinition/"&LogicalModels!$A$5 -> http://hl7.eu/fhir/ig/oah/StructureDefinition/Sample | B12: http://hl7.eu/fhir/ig/oah/StructureDefinition/location-oah | C12: =SampleOah!A7 -> site.formReference | D12: =SampleOah!D7 -> Form Reference | E12: Location.extension[referenceForm] | G12: equivalent

Sheet SampleOah
A1: Element | B1: Cardinality | C1: Datatype | D1: Short | E1: Definition
A2: site | B2: 1..1 | C2: Base | D2: Sampling Site | E2: Sampling Site
A3: site.identifier | B3: 1..* | C3: Base | D3: Site identifier | E3: Site identifier
A4: site.name | B4: 1..* | C4: Base | D4: Site Name | E4: Site Name
A5: site.gps | B5: 0..1 | C5: Base | D5: GPS | E5: GPS
A6: site.characteristics | B6: 0..* | C6: Base | D6: Characteristics | E6: Characteristics
